Workbook
Name _IME1: #REF!
Name _IME1: #REF!
Name _IME1: #REF!
Name _IME1: #REF!
Name _IME1: #REF!
Name _IME1: #REF!
Name DB名: #REF!
Name ENID: #REF!
Name hani: #REF!
Name hani: #REF!
Name hani: #REF!
Name IME: #REF!
Name IME: #REF!
Name IME: #REF!
Name IME: #REF!
Name NOTNULL: #REF!
Name TABLE_ENT: #REF!
Name TABLE_NAME: #REF!
Name TABLE_NAME: #REF!
Name TABLE_NAME: #REF!
Name あ1: #REF!
Name コントロール: #REF!
Name コントロール: #REF!
Name コントロール: #REF!
Name コントロール: #REF!
Name コントロール: #REF!
Name コントロール: #REF!
Name サブシステム名: #REF!
Name システム名: #REF!
Name データ型: #REF!
Name データ型: #REF!
Name データ型: #REF!
Name データ型: #REF!
Name データ型: #REF!
Name データ型: #REF!
Name データ名: #REF!
Name データ名: #REF!
Name データ名: #REF!
Name パターン: #REF!
Name パターン: #REF!
Name パターン: #REF!
Name パターン: #REF!
Name パターン: #REF!
Name パターン: #REF!
Name 基本キー: #REF!
Name 基本キー: #REF!
Name 基本キー: #REF!
Name 更新者: #REF!
Name 更新日: #REF!
Name 更新日: #REF!
Name 更新日: #REF!
Name 行長: #REF!
Name 項目ID: #REF!
Name 項目ID: #REF!
Name 項目ID: #REF!
Name 項目No: #REF!
Name 項目No: #REF!
Name 項目No: #REF!
Name 項目名: #REF!
Name 項目名: #REF!

Sheet 変更履歴
A1: 業務機能設計書
A2: 項番 | C2: 変更年月日 | H2: 変更シート | O2: 変更内容 | AS2: 種別 | AV2: バージョン | AZ2: 作成 | BE2: 審査 | BJ2: 承認
A3: 1 | C3: 45974 | H3: － | O3: 新規作成 | AS3: 新規 | AV3: ー | AZ3: 内田 | BE3: 中川 | BJ3: 松本
A4: 2 | C4: 46017 | H4: 設計概要②_定期オーダー開始日終了日補足 | O4: 定期オーダー開始日・終了日の検索条件を変更 | AS4: 変更 | AV4: 0.1 | AZ4: 内田 | BE4: 中川 | BJ4: 松本
A5: 3 | C5: 46017 | H5: 仕様概要 画面項目定義 画面状態定義 画面取得元定義 | O5: 定期フラグを活動フラグに名称変更 | AS5: 変更 | AV5: 0.1 | AZ5: 内田 | BE5: 中川 | BJ5: 松本
A6: 4 | C6: 46017 | H6: 設計概要①_概要補足 | O6: 活動フラグ更新時の補足説明を追加 | AS6: 追加 | AV6: 0.1 | AZ6: 内田 | BE6: 中川 | BJ6: 松本
A7: 5 | C7: 46017 | H7: 画面項目チェック定義 | O7: 強制作成ボタン押下時のチェック処理を追加 | AS7: 追加 | AV7: 0.1 | AZ7: 内田 | BE7: 中川 | BJ7: 松本
A8: 6 | C8: 46017 | H8: 仕様概要 画面項目定義 画面状態定義 画面取得元定義 | O8: 明細に項目追加 ・定期オーダー更新者 ・定期オーダー更新日 ・前回バッチ実行日 ・前回オーダー作成日 検索条件に項目追加 ・スケジュール管轄組織コード | AS8: 追加 | AV8: 0.1 | AZ8: 内田 | BE8: 中川 | BJ8: 松本
A9: 7 | C9: 46017 | H9: 設計概要①_概要補足 | O9: 履歴データ取得に関する動作を記載 | AS9: 追加 | AV9: 0.1 | AZ9: 内田 | BE9: 中川 | BJ9: 松本
A10: 8 | C10: 46017 | H10: 仕様概要 | O10: 定期オーダーを手動で実行する「強制作成ボタン」を追加 | AS10: 追加 | AV10: 0.1 | AZ10: 内田 | BE10: 中川 | BJ10: 松本
A11: 9 | C11: 46017 | H11: 画面項目定義 画面状態定義 | O11: 明細項目の「活動フラグ」は変更可能項目に変更 | AS11: 変更 | AV11: 0.1 | AZ11: 増野 | BE11: 中川 | BJ11: 松本
A12: 10 | C12: 46058 | H12: 仕様概要 | O12: 画面イメージ差し替え | AS12: 変更 | AV12: 0.1 | AZ12: 秋山 | BE12: 中川 | BJ12: 松本
A13: 11 | C13: 46077 | H13: 仕様概要 画面項目定義 画面状態定義 画面取得元定義 | O13: 検索条件に項目追加 ・組織名 ・定期オーダー作成日 ・Excel出力ボタン 明細に項目追加 ・引取先名 ・スケジュール管轄組織コード ・組織名 | AS13: 追加 | AV13: 0.1 | AZ13: 増野 | BE13: 中川 | BJ13: 松本
A14: 12 | C14: 46077 | H14: 仕様概要 設計概要①_概要補足 画面項目定義 画面状態定義 画面項目チェック定義 画面取得元定義 | O14: 明細から項目削除 ・選択 フッタからボタン削除 ・定期オーダー削除ボタン ・強制作成ボタン ・更新ボタン(活動フラグは入力画面で更新) | AS14: 削除 | AV14: 0.1 | AZ14: 増野 | BE14: 中川 | BJ14: 松本
... A20: 18 | C20: 46092 | H20: 仕様概要 | O20: 画面イメージ差し替え | AS20: 変更 | AV20: 0.1 | AZ20: 堀 | BE20: 中川 | BJ20: 松本
A21: 19
A22: 20
A23: 21
A24: 22
A25: 23
A26: 24
A27: 25
A28: 26
A29: 27
A30: 28
A31: 29
A32: 30
... A36: 34
C37: 凡例 | K37: 「種別」：新規、追加、変更、削除のいずれかを指定

Sheet 仕様概要
A1: ONEsLOGI Cloud / WMS | G1: 業務機能設計 | N1: 業務ＩＤ | R1: U-OR-140-P
G2: 仕様概要 | N2: 業務名称 | R2: オーダー | Z2: 機能名称 | AD2: 定期オーダー一覧
C4: 凡例
B9: １．画面イメージ
M40: 明細続き
M64: 「備考」にマウスカーソルを合わせたとき
M65: 全文を表示するツールチップを表示
B77: ２．機能概要
C79: <全体概要>
D81: １.定期オーダー一覧画面
E82: 定期的に発生するオーダーを事前に登録した、指定スケジュールを管理する機能。
E83: 定期オーダーは返却オーダーのみ登録可能とする。
E85: ・ | F85: 登録されている定期オーダーを検索・Excel出力が可能。
E86: ・ | F86: 検索した定期オーダーから、定期オーダー入力（詳細）画面への遷移が可能（編集ボタン、詳細ボタン、複写ボタン）
E87: ・ | F87: 1つのスケジュールで複数のオーダー登録を管理。
E88: ・ | F88: 作成した定期オーダーの稼働/停止の制御を可能とする。
E89: ・ | F89: 単一スケジュールの手動実行を可能とする。(強制作成ボタン)
C91: <アクション>
D93: 利用者 | J93: オーダー業務管理者
J94: オーダー業務作業者
J95: 調達管理部門管理者
J96: 調達管理部門作業者
D98: 利用タイミング | J98: 随時
D99: ① | E99: 実行アクション | M99: ・「検索」ボタン
F101: 処理概要 | M101: ・検索条件に従い、定期オーダー情報のデータを取得する。
F103: 処理前提 | M103: ・無し
F105: 補足等 | M105: ・無し
F107: 出力順 | M107: ・スケジュールNo（降順）
E109: 実行後アクション
F110: 実行後アクション | M110: ・定期オーダー情報データを取得し、明細画面を表示する。
F112: 完了処理 | M112: ・無し
D114: ② | E114: 実行アクション | M114: ・「Excel出力」ボタン
F116: 処理概要 | M116: ・検索条件に従い、定期オーダーのデータをExcel出力する。
F118: 処理前提 | M118: ・無し
F120: 補足等 | M120: ・無し
F122: 出力順 | M122: ・スケジュールNo（降順）
E124: 実行後アクション
F125: 実行後アクション | M125: ・定期オーダーのデータを取得し、Excelデータをダウンロードできる。
F127: 完了処理 | M127: ・無し
D130: 利用タイミング | J130: 定期オーダー更新・参照時
...

Sheet 仕様概要1
A1: ONEsLOGI Cloud / WMS | G1: 業務機能設計 | N1: 業務ＩＤ | R1: U-OR-150-P※機能IDを記載
G2: 仕様概要 | N2: 業務名称 | R2: オーダー※業務区分を記載 | Z2: 機能名称 | AD2: 入出庫依頼一覧※機能名を記載
C4: 凡例
B9: １．画面イメージ
B50: ２．機能概要
C52: <全体概要>
D54: 1
C65: <ボタンアクション>
D67: 利用者
D69: 利用タイミング
D70: ① | E70: 実行アクション
F72: 利用目的
F74: 利用方法
F76: 処理概要
F79: 処理前提
F83: 補足等
F85: 出力順
E87: 実行後アクション
F88: 実行後アクション
F90: 完了処理
D92: ⑤ | E92: 実行アクション
F94: 利用目的
F96: 利用方法
F98: 処理概要
F105: 処理前提
F109: 補足等
F111: 出力順
E113: 実行後アクション
F114: 実行後アクション
F116: 完了処理
D119: 利用タイミング
D120: ② | E120: 実行アクション
F122: 利用目的
F124: 利用方法
F126: 処理概要
F128: 処理前提
F132: 補足等
F134: 出力順
E136: 実行後アクション
F137: 実行後アクション
...

Sheet マッピング定義
A1: ONEsLOGI Cloud / WMS | G1: =仕様概要1!G1 -> 業務機能設計 | N1: 業務ＩＤ | R1: =仕様概要1!R1 -> U-OR-150-P※機能IDを記載 | Z1: 機能ＩＤ | AD1: =仕様概要1!AD1 -> 0 | AR1: 作者 | AU1: 大沼 | AX1: 作成日 | BA1: 44749 | BE1: 承認者
G2: 項目仕様 | N2: 業務名称 | R2: =仕様概要1!R2 -> オーダー※業務区分を記載 | Z2: 機能名称 | AD2: =仕様概要1!AD2 -> 入出庫依頼一覧※機能名を記載 | AR2: 更新者 | AX2: 更新日 | BE2: 承認日
B4: 1.データ取得 | H4: ※メインテーブルは、t_receive_plan_b
E6: 項目名 | R6: 項目ID | AE6: マッピング | AX6: 備考欄
B8: 入力 | E8: 返却オーダー番号
B9: 入力 | E9: 拠点分類
B10: 入力 | E10: 親拠点（使用者）
B11: 入力 | E11: 子拠点
B12: 入力 | E12: 受渡方法
B13: 入力 | E13: 納品先名
B14: 入力 | E14: 納品先郵便番号
B15: 入力 | E15: 納品先住所
B16: 入力 | E16: 納品先電話番号
B17: 入力 | E17: 納品先担当者
B18: 入力 | E18: 備考
B19: 入力 | E19: 品目コード
... B27: 入力 | E27: 備考

Sheet 設計概要①_概要補足
B4: １．設計概要
C6: ①概要補足
D8: <1.初期表示>
E10: ■検索条件欄
F11: ・ | G11: 「定期オーダー開始日」Fromの初期値はシステム管理業務日付の前月末とする。
E13: ■ソート順
F14: スケジュールNo（降順）
D17: <2.他画面より遷移時の複写項目>
E19: ※この画面は他画面からの複写はないため不要
D21: <3.画面制御>
D24: <更新ボタン>
F26: 更新処理
G27: 活動フラグを更新する。
H28: 活動フラグを「非活動」⇒「活動中」に更新した場合、次オーダーが作成されるのは翌月分からとする。 ※当月分は作成されない
I29: 例：毎月15日に定期作成バッチが実行
K30: ・1/10に活動フラグを非活動⇒活動した場合、1/15(当月)にバッチ実行され、翌月分(２月分)のオーダーから作成される
K31: ・1/16に活動フラグを非活動⇒活動した場合、2/15(翌月)にバッチ実行され、翌々月分(３月分)のオーダーから作成される
G33: 定期オーダースケジュールを更新する。
H34: スケジュール情報を更新した際は、修正履歴を共通機能で管理する。
D36: <強制作成ボタン>
F38: 作成処理
G39: 定期オーダースケジュールに基づき、翌月分のオーダーを作成する。
H40: 翌月分の定期オーダーが作成済みの場合、強制作成はエラーとなる。
I41: ・当月の定期バッチ実行日前に強制作成した場合（翌月定期オーダー未作成）
J42: ⇒翌月のオーダーが作られる ※当月の定期バッチ実行はスキップ
I43: ・当月の定期バッチ実行日後に強制実行した場合（翌月定期オーダー作成済み）
J44: ⇒強制作成がエラーとなる
H46: 作成されたオーダーの作成者には強制作成を実行したユーザーを登録する。

Sheet 設計概要②_定期オーダー開始日終了日補足
B4: １．設計概要
C6: ②定期オーダー開始日終了日補足
D8: <1.検索範囲>
E10: ■検索条件
F11: ・ | G11: FromToの両方に入力がある場合
H12: (スケジュール.開始日 ≦ 検索.終了日 かつ、 スケジュール.終了日 ≧ 検索.開始日 )
F13: ・ | G13: Fromのみ
H14: (スケジュール.終了日 ≧ 検索.開始日 )
F15: ・ | G15: Toのみ
H16: (スケジュール.開始日 ≦ 検索.終了日 )
F18: 例えば、検索条件に2025/10/1(From)～2025/11/1(To)を設定した場合に、「2025/10/1」は全ての定期オーダーがスケジュールされているため、
F19: 定期オーダーA,B,Cの全てが検索にヒットする。

Sheet 画面項目定義
A4: 画面項目定義
B6: No | C6: グループ名 | D6: 論理項目名 | E6: 論理項目種別 | F6: ドメイン | G6: 必須 | H6: 初期値 | I6: 備考
B7: =ROW()-6 -> 1 | C7: ヘッダ | D7: スケジュールNo | E7: テキストボックス | F7: - | G7: -
B8: =ROW()-6 -> 2 | D8: スケジュールタイトル | E8: テキストボックス | F8: - | G8: - | I8: 部分一致検索
B9: =ROW()-6 -> 3 | D9: 定期オーダー開始日(From) | E9: テキストボックス | F9: 年月日 | G9: - | H9: 業務日付の前月末
B10: =ROW()-6 -> 4 | D10: 定期オーダー終了日(To) | E10: テキストボックス | F10: 年月日 | G10: -
B11: =ROW()-6 -> 5 | D11: 活動フラグ(活動中/非活動) 有効フラグ | E11: コンボボックス | F11: - | G11: - | I11: 活動中/非活動 有効／無効
B12: =ROW()-6 -> 6 | D12: スケジュール管轄組織コード | E12: テキストボックス | F12: 組織コード | G12: - | I12: 定期オーダースケジュールを管理する組織 ※スケジュール登録時にマニュアルで設定
B13: =ROW()-6 -> 7 | D13: 検索(組織コード) | E13: リンクボタン | F13: - | G13: -
B14: =ROW()-6 -> 8 | D14: 組織名 | E14: テキスト出力 | F14: 組織名 | G14: -
B15: =ROW()-6 -> 9 | D15: 定期オーダー作成日 | E15: テキスト出力 | F15: - | G15: - | H15: 定期オーダー作成日：毎月○○日 | I15: ○○は定期オーダーの作成日をマスタから取得して表示
B16: =ROW()-6 -> 10 | D16: 検索 | E16: ボタン | F16: - | G16: -
B17: =ROW()-6 -> 11 | D17: Excel出力 | E17: ボタン | F17: - | G17: -
B18: =ROW()-6 -> 12 | C18: 明細 | D18: 選択 | E18: チェックボックス | F18: - | G18: -
B19: =ROW()-6 -> 13 | D19: 編集 | E19: ボタン | F19: - | G19: -
B20: =ROW()-6 -> 14 | D20: 詳細 | E20: ボタン | F20: - | G20: -
B21: =ROW()-6 -> 15 | D21: 複写 | E21: ボタン | F21: - | G21: -
B22: =ROW()-6 -> 16 | D22: スケジュールNo | E22: テキスト出力 | F22: - | G22: -
B23: =ROW()-6 -> 17 | D23: スケジュールタイトル | E23: テキスト出力 | F23: - | G23: -
B24: =ROW()-6 -> 18 | D24: 登録日 | E24: テキスト出力 | F24: 年月日 | G24: -
B25: =ROW()-6 -> 19 | D25: 開始日 | E25: テキスト出力 | F25: 年月日 | G25: -
B26: =ROW()-6 -> 20 | D26: 終了日 | E26: テキスト出力 | F26: 年月日 | G26: -
B27: =ROW()-6 -> 21 | D27: 条件:週 | E27: テキスト出力 | F27: - | G27: -
B28: =ROW()-6 -> 22 | D28: 条件:曜日 | E28: テキスト出力 | F28: - | G28: - | I28: スケジュールパターンを「/」区切りで表示
B29: =ROW()-6 -> 23 | D29: 条件:日 | E29: テキスト出力 | F29: - | G29: - | I29: スケジュールパターンを「/」区切りで表示
B30: =ROW()-6 -> 24 | D30: 引取先名 | E30: テキスト出力 | F30: - | G30: - | I30: 先頭の明細の取引先を代表で表示
B31: =ROW()-6 -> 25 | D31: スケジュール管轄組織コード | E31: テキスト出力 | F31: 組織コード | G31: -
B32: =ROW()-6 -> 26 | D32: 組織名 | E32: テキスト出力 | F32: 組織名 | G32: -
B33: =ROW()-6 -> 27 | D33: 活動フラグ有効フラグ | E33: テキスト出力 | F33: - | G33: -
B34: =ROW()-6 -> 28 | D34: 備考 | E34: テキスト出力 | F34: - | G34: -
B35: =ROW()-6 -> 29 | D35: 前回バッチ実行日 前回オーダー作成日 | E35: テキスト出力 | F35: - | G35: -
B36: =ROW()-6 -> 30 | D36: 前回オーダー作成日 前回オーダー最終引取日 | E36: テキスト出力 | F36: - | G36: - | I36: 前回作成したオーダー中で最新の引取日を設定 ※1/10、1/20、1/30のように複数日を作成した場合は1/30を表示
B37: =ROW()-6 -> 31 | D37: 定期オーダー更新者 | E37: テキスト出力 | F37: - | G37: -
B38: =ROW()-6 -> 32 | D38: 定期オーダー更新日 | E38: テキスト出力 | F38: - | G38: -
B39: =ROW()-6 -> 33 | C39: フッタ | D39: 定期オーダー削除 | E39: ボタン | F39: - | G39: -
B40: =ROW()-6 -> 34 | D40: 定期オーダーコピー | E40: ボタン | F40: - | G40: -
B41: =ROW()-6 -> 35 | D41: 定期オーダー作成 | E41: ボタン | F41: - | G41: -
B42: =ROW()-6 -> 36 | D42: 定期オーダー詳細 | E42: ボタン | F42: - | G42: -
B43: =ROW()-6 -> 37 | D43: 強制作成 | E43: ボタン | F43: - | G43: -
B44: =ROW()-6 -> 38 | D44: 更新 | E44: ボタン | F44: - | G44: -
...

Sheet 画面状態定義
A4: 画面状態定義
B6: 画面項目 | E6: 画面状態
B7: 項番 | C7: グループ名 | D7: 論理項目名 | E7: 初期表示 | F7: 検索
B10: =ROW()-9 -> 1 | C10: ヘッダ | D10: スケジュールNo | E10: 入力可能 | F10: 入力可能
B11: =ROW()-9 -> 2 | D11: スケジュールタイトル | E11: 入力可能 | F11: 入力可能
B12: =ROW()-9 -> 3 | D12: 定期オーダー開始日(From) | E12: 入力可能 | F12: 入力可能
B13: =ROW()-9 -> 4 | D13: 定期オーダー終了日(To) | E13: 入力可能 | F13: 入力可能
B14: =ROW()-9 -> 5 | D14: 活動フラグ有効フラグ | E14: 入力可能 | F14: 入力可能
B15: =ROW()-9 -> 6 | D15: スケジュール管轄組織コード | E15: 入力可能 | F15: 入力可能
B16: =ROW()-9 -> 7 | D16: 検索(組織コード) | E16: 押下可能 | F16: 押下可能
B17: =ROW()-9 -> 8 | D17: 組織名 | E17: 入力不可 | F17: 入力不可
B18: =ROW()-9 -> 9 | D18: 定期オーダー作成日 | E18: 入力不可 | F18: 入力不可
B19: =ROW()-9 -> 10 | D19: 検索 | E19: 押下可能 | F19: 押下可能
B20: =ROW()-9 -> 11 | D20: Excel出力 | E20: 押下可能 | F20: 押下可能
B21: =ROW()-9 -> 12 | C21: 明細 | D21: 選択 | E21: 非表示 | F21: 表示
B22: =ROW()-9 -> 13 | D22: 編集 | E22: 非表示 | F22: 表示
B23: =ROW()-9 -> 14 | D23: 詳細 | E23: 非表示 | F23: 表示
B24: =ROW()-9 -> 15 | D24: 複写 | E24: 非表示 | F24: 表示
B25: =ROW()-9 -> 16 | D25: スケジュールNo | E25: 非表示 | F25: 表示
B26: =ROW()-9 -> 17 | D26: スケジュールタイトル | E26: 非表示 | F26: 表示
B27: =ROW()-9 -> 18 | D27: 登録日 | E27: 非表示 | F27: 表示
B28: =ROW()-9 -> 19 | D28: 開始日 | E28: 非表示 | F28: 表示
B29: =ROW()-9 -> 20 | D29: 終了日 | E29: 非表示 | F29: 表示
B30: =ROW()-9 -> 21 | D30: 条件:週 | E30: 非表示 | F30: 表示
B31: =ROW()-9 -> 22 | D31: 条件:曜日 | E31: 非表示 | F31: 表示
B32: =ROW()-9 -> 23 | D32: 条件:日 | E32: 非表示 | F32: 表示
B33: =ROW()-9 -> 24 | D33: 引取先名 | E33: 非表示 | F33: 表示
... B41: =ROW()-9 -> 32 | D41: 定期オーダー更新日 | E41: 非表示 | F41: 表示
B42: =ROW()-9 -> 33 | C42: フッタ | D42: 定期オーダー削除 | E42: 押下可能 | F42: 押下可能
B43: =ROW()-9 -> 34 | D43: 定期オーダーコピー | E43: 押下可能 | F43: 押下可能
B44: =ROW()-9 -> 35 | D44: 定期オーダー作成 | E44: 押下可能 | F44: 押下可能
B45: =ROW()-9 -> 36 | D45: 定期オーダー詳細 | E45: 押下可能 | F45: 押下可能
B46: =ROW()-9 -> 37 | D46: 強制作成 | E46: 押下可能 | F46: 押下可能
B47: =ROW()-9 -> 38 | D47: 更新 | E47: 押下可能 | F47: 押下可能

Sheet 画面項目チェック定義
A4: 画面項目チェック定義
B6: チェック対象 イベント | I6: 項目名称 | O6: エラータイトル | U6: 制約(エラーケース) | AL6: メッセージID | AT6: 置換文字列
B8: 検索 Excel出力 | I8: 定期オーダー開始日(From) | O8: 日付整合性チェック | U8: 定期オーダー開始日(From) > 定期オーダー終了日(To)の場合、エラー | AL8: （新規） | BE8: 定期オーダー開始日(From)は定期オーダー終了日(To)以前の日付を入力してください。
B9: 検索 Excel出力 | I9: － | O9: 検索結果チェック | U9: 取得結果が0件の場合 | BE9: 該当データが存在しません。
B10: 定期オーダー削除 | O10: 更新対象チェック | U10: レコード未選択時、エラー | BE10: 明細が選択されていません。
B11: 定期オーダーコピー | O11: 更新対象チェック | U11: レコード未選択時、エラー | BE11: 明細が選択されていません。
B12: 定期オーダー詳細 | O12: 更新対象チェック | U12: レコード未選択時、エラー | BE12: 明細が選択されていません。
B13: 更新 | O13: 更新対象チェック | U13: レコード未選択時、エラー | BE13: 明細が選択されていません。
B14: 強制作成 | O14: 作成対象チェック | U14: レコード未選択時、エラー | AL14: （新規） | BE14: 明細が選択されていません。
B15: 強制作成 | O15: 作成対象チェック | U15: レコード複数選択時、エラー | AL15: （新規） | BE15: 強制作成は複数明細を選択することはできません。
B16: 強制作成 | O16: 作成対象チェック | U16: 活動フラグが非活動の場合、エラー | AL16: （新規） | BE16: 活動フラグが非活動の明細を選択することはできません。
B17: 強制作成 | O17: 作成対象チェック | U17: 翌月分が作成済みの場合、エラー | AL17: （新規） | BE17: 翌月分の定期オーダーが作成済の明細を選択することはできません。

Sheet 画面取得元定義
A4: 画面取得元定義
E5: レビュー対象外 | F5: レビュー対象外 | I5: レビュー対象外
B6: 画面項目 | E6: 画面状態
B7: 項番 | C7: グループ名 | D7: 論理項目名 | E7: 初期表示 | F7: 検索 | G7: ロストフォーカス | I7: コンボボックス
B9: =ROW()-8 -> 1 | C9: ヘッダ | D9: スケジュールNo
B10: =ROW()-8 -> 2 | D10: スケジュールタイトル
B11: =ROW()-8 -> 3 | D11: 定期オーダー開始日(From)
B12: =ROW()-8 -> 4 | D12: 定期オーダー終了日(To)
B13: =ROW()-8 -> 5 | D13: 活動フラグ有効フラグ
B14: =ROW()-8 -> 6 | D14: スケジュール管轄組織コード
B15: =ROW()-8 -> 7 | D15: 検索(組織コード)
B16: =ROW()-8 -> 8 | D16: 組織名
B17: =ROW()-8 -> 9 | D17: 定期オーダー作成日
B18: =ROW()-8 -> 10 | D18: 検索
B19: =ROW()-8 -> 11 | D19: Excel出力
B20: =ROW()-8 -> 12 | C20: 明細 | D20: 選択
B21: =ROW()-8 -> 13 | D21: 編集
B22: =ROW()-8 -> 14 | D22: 詳細
B23: =ROW()-8 -> 15 | D23: 複写
B24: =ROW()-8 -> 16 | D24: スケジュールNo
B25: =ROW()-8 -> 17 | D25: スケジュールタイトル
B26: =ROW()-8 -> 18 | D26: 登録日
B27: =ROW()-8 -> 19 | D27: 開始日
B28: =ROW()-8 -> 20 | D28: 終了日
B29: =ROW()-8 -> 21 | D29: 条件:週
B30: =ROW()-8 -> 22 | D30: 条件:曜日
B31: =ROW()-8 -> 23 | D31: 条件:日
B32: =ROW()-8 -> 24 | D32: 引取先名
... B40: =ROW()-8 -> 32 | D40: 定期オーダー更新日
B41: =ROW()-8 -> 33 | C41: フッタ | D41: 定期オーダー削除
B42: =ROW()-8 -> 34 | D42: 定期オーダーコピー
B43: =ROW()-8 -> 35 | D43: 定期オーダー作成
B44: =ROW()-8 -> 36 | D44: 定期オーダー詳細
B45: =ROW()-8 -> 37 | D45: 強制作成
B46: =ROW()-8 -> 38 | D46: 更新

Sheet 画面遷移図
B4: １．画面遷移図

Sheet テーブル移送表(定期オーダースケジュール）
A5: テーブル移送表
A6: テーブル名 | C6: 定期オーダースケジュール
A8: 項番 | B8: 項目名 | C8: ①更新の場合 | E8: 備考
A9: =ROW()-8 -> 1 | B9: スケジュールID
A10: =ROW()-8 -> 2 | B10: スケジュールNo
A11: =ROW()-8 -> 3 | B11: スケジュールタイトル
A12: =ROW()-8 -> 4 | B12: 登録日
A13: =ROW()-8 -> 5 | B13: 定期オーダー開始日
A14: =ROW()-8 -> 6 | B14: 定期オーダー終了日
A15: =ROW()-8 -> 7 | B15: 入庫日の調整(日)
A16: =ROW()-8 -> 8 | B16: 請求終了日の調整(日)
A17: =ROW()-8 -> 9 | B17: メモ
A18: =ROW()-8 -> 10 | B18: 活動フラグ | C18: 画面.活動フラグ | E18: 0:活動中/1:非活動
A19: =ROW()-8 -> 11 | B19: 前回バッチ実行日
A20: =ROW()-8 -> 12 | B20: 前回オーダー作成日
A21: =ROW()-8 -> 13 | B21: 定期オーダー更新者
A22: =ROW()-8 -> 14 | B22: 定期オーダー更新日
A23: =ROW()-8 -> 15 | B23: 作成者
A24: =ROW()-8 -> 16 | B24: 作成日
A25: =ROW()-8 -> 17 | B25: 最終更新者 | C25: ログインユーザ.ユーザID
A26: =ROW()-8 -> 18 | B26: 最終更新日 | C26: システム日付
A27: =ROW()-8 -> 19 | B27: 最終更新プログラムID | C27: プログラムID
A28: =ROW()-8 -> 20 | B28: 削除フラグ | C28: '0'
A29: =ROW()-8 -> 21

Sheet テーブル移送表(定期オーダースケジュールパターン)
A5: テーブル移送表
A6: テーブル名 | C6: 定期オーダースケジュールパターン
A8: 項番 | B8: 項目名 | C8: ①登録の場合 | E8: 備考
A9: =ROW()-8 -> 1 | B9: スケジュールパターンID
A10: =ROW()-8 -> 2 | B10: スケジュールID
A11: =ROW()-8 -> 3 | B11: パターン区分 | E11: 1:週次、2:月次
A12: =ROW()-8 -> 4 | B12: 曜日 | E12: 1:月曜～7:日曜
A13: =ROW()-8 -> 5 | B13: 日付 | E13: 1～31
A14: =ROW()-8 -> 6 | B14: 週回数 | E14: 1:第1～5:第5
A15: =ROW()-8 -> 7 | B15: 週間間隔 | E15: 1:毎週、2:隔週
A16: =ROW()-8 -> 8 | B16: 最終作成日
A17: =ROW()-8 -> 9 | B17: 作成者
A18: =ROW()-8 -> 10 | B18: 作成日
A19: =ROW()-8 -> 11 | B19: 最終更新者
A20: =ROW()-8 -> 12 | B20: 最終更新日
A21: =ROW()-8 -> 13 | B21: 最終更新プログラムID
A22: =ROW()-8 -> 14 | B22: 削除フラグ
A23: =ROW()-8 -> 15

Sheet 画面イメージ
C3: 返却オーダー入力
E7: 返却オーダー番号 | S7: 拠点分類 | AG7: 親拠点（使用者） | AV7: 子拠点
S8: 1:保管 | AC8: ▽ | AG8: 00001:東京支店 | AQ8: ▽ | AV8: 10000:東陽町拠点 | BF8: ▽
E11: 受渡方法 | S11: 引取先名 | AG11: 引取先郵便番号 | AV11: 引取先住所1（都道府県市区郡）
E12: 1:ZLC手配 | O12: ▽ | S12: 東陽町拠点 | AG12: xxx-xxxx | AV12: 東京都江東区
E15: 引取先住所2（町名） | S15: 引取先住所3（建物・担当者） | AG15: 引取先電話番号 | AV15: 引取先担当者
E16: 東陽7-2-14 | S16: MKビル | AG16: XXX-XXXX-XXXX | AV16: 担当者01
E19: その他（ユーピーアールへの連絡欄）
D26: 明細
F27: 品目コード | K27: 品目名称 | O27: 数量 | R27: 予定在庫 | U27: デポ納品日 | AB27: 返却先デポCD | AG27: 返却先デポ名称 | AK27: 返却状況 | AP27: 備考（明細）
D29: ☑ | F29: 14 | I29: 🔍 | K29: パレット11型 | O29: 20 | R29: 20 | U29: 44692 | Z29: 📅 | AB29: 000001 | AE29: 🔍 | AG29: 東京デポ | AK29: 未登録
D31: ☑ | F31: 14 | I31: 🔍 | K31: パレット11型 | O31: 30 | R31: 30 | U31: 44693 | Z31: 📅 | AB31: 000001 | AE31: 🔍 | AG31: 東京デポ | AK31: 未登録
D41: 行追加 | I41: 行コピー | N41: 行削除 | BD41: 一時保存 | BI41: 登 録
C47: 返却オーダー入力
E51: 返却オーダー番号 | S51: 拠点分類 | AG51: 親拠点（使用者） | AV51: 子拠点
E52: H2205Z0001 | S52: 1:保管 | AC52: ▽ | AG52: 00001:東京支店 | AQ52: ▽ | AV52: 10000:東陽町拠点 | BF52: ▽
E55: 受渡方法 | S55: 引取先名 | AG55: 引取先郵便番号 | AV55: 引取先住所1（都道府県市区郡）
E56: 1:ZLC手配 | O56: ▽ | S56: 東陽町拠点 | AG56: xxx-xxxx | AV56: 東京都江東区
E59: 引取先住所2（町名） | S59: 引取先住所3（建物・担当者） | AG59: 引取先電話番号 | AV59: 引取先担当者
E60: 東陽7-2-14 | S60: MKビル | AG60: XXX-XXXX-XXXX | AV60: 担当者01
E63: 備考
D70: 明細
F71: 品目 | O71: 数量 | R71: 予定在庫 | U71: デポ納品日 | AB71: 返却先デポ | AK71: ステータス | AP71: 指図No | AY71: 備考
D73: ☑ | F73: S000001 | I73: 🔍 | K73: 11型 | O73: 20 | R73: 20 | U73: 44692 | Z73: 📅 | AB73: 000001 | AE73: 🔍 | AG73: 東京デポ | AK73: 未登録 | AP73: S0011/S0012/S0013
D75: ☑ | F75: S000001 | I75: 🔍 | K75: 11型 | O75: 30 | R75: 30 | U75: 44693 | Z75: 📅 | AB75: 000001 | AE75: 🔍 | AG75: 東京デポ | AK75: 未登録 | AP75: S0021/S0022/S0023…
D85: 行追加 | I85: 行コピー | N85: 行削除 | BD85: 一時保存 | BI85: 登 録
C89: 返却オーダー入力
E93: 返却オーダー番号 | S93: 拠点分類 | AG93: 親拠点（使用者） | AV93: 子拠点
E94: H2205Z0001 | S94: 1:保管 | AC94: ▽ | AG94: 00001:東京支店 | AQ94: ▽ | AV94: 10000:東陽町拠点 | BF94: ▽
E97: 受渡方法 | S97: 引取先名 | AG97: 引取先郵便番号 | AV97: 引取先住所1（都道府県市区郡）
E98: 1:ZLC手配 | O98: ▽ | S98: 東陽町拠点 | AG98: xxx-xxxx | AV98: 東京都江東区
E101: 引取先住所2（町名） | S101: 引取先住所3（建物・担当者） | AG101: 引取先電話番号 | AV101: 引取先担当者
E102: 東陽7-2-14 | S102: MKビル | AG102: XXX-XXXX-XXXX | AV102: 担当者01
E105: 備考
D112: 明細
F113: 品目 | O113: 数量 | R113: 予定在庫 | U113: デポ納品日 | AB113: 返却先デポ | AK113: ステータス | AP113: 備考
D115: ☑ | F115: S000001 | I115: 🔍 | K115: 11型 | O115: 20 | R115: 20 | U115: 44692 | Z115: 📅 | AB115: 000001 | AE115: 🔍 | AG115: 東京デポ | AK115: 一時保存
D117: ☑ | F117: S000001 | I117: 🔍 | K117: 11型 | O117: 30 | R117: 30 | U117: 44693 | Z117: 📅 | AB117: 000001 | AE117: 🔍 | AG117: 東京デポ | AK117: 却下
D119: ☑ | F119: S000001 | I119: 🔍 | K119: 11型 | O119: 30 | R119: 30 | U119: 44691 | Z119: 📅 | AB119: 000001 | AE119: 🔍 | AG119: 東京デポ | AK119: 承認済み
D127: 行追加 | I127: 行コピー | N127: 行削除 | BD127: 一時保存 | BI127: 登 録

Sheet 選択リスト(非表示)
A1: ヘッダ・フッタ区分 | C1: タイプ | E1: 編集 | G1: 必須 | I1: 入力タイプ | K1: 検索条件 | M1: メッセージタイプ | O1: タイプ(IF定義用) | Q1: 必須(IF定義用)
A2: 検索 | C2: text | E2: 可 | G2: 必須 | I2: 数字 | K2: 完全一致 | M2: エラー | O2: 文字列 | Q2: 必須
A3: 入力 | C3: dropdown | E3: 不可 | G3: 任意 | I3: 数字と- | K3: 前方一致 | M3: 情報 | O3: 数値 | Q3: 任意
A4: 明細 | C4: calcnumber | I4: 英字 | K4: 後方一致 | M4: 確認 | O4: 日付 | Q4: 無効
A5: フッタ | C5: date | I5: 英字と- | K5: 部分一致 | M5: 警告 | O5: 日時
A6: 凡例 | C6: number | I6: 英数字 | K6: From-To
A7: グラフ | C7: button | I7: 英数字と-
A8: リンク | C8: checkbox | I8: 英数字と記号
A9: 入力1 | C9: datetime | I9: 半角文字
A10: 入力2 | C10: textarea | I10: 全角文字
A11: 入力3 | C11: password | I11: 時刻(hh:mm)
A12: 入力4 | C12: label | I12: 全て
A13: 入力5
A14: 明細1
A15: 明細2
A16: 明細3
A17: 明細4
A18: 明細5
A19: フッタ1
A20: フッタ2
A21: フッタ3
A22: フッタ4
A23: フッタ5
A24: 入力6
... A29: 入力11
